Traceback (most recent call last):
  File "/home/z0272571a@CAMPUS.CSIC.ES/.local/lib/python3.9/site-packages/jupyter_cache/executors/utils.py", line 58, in single_nb_execution
    executenb(
  File "/home/z0272571a@CAMPUS.CSIC.ES/.local/lib/python3.9/site-packages/nbclient/client.py", line 1314, in execute
    return NotebookClient(nb=nb, resources=resources, km=km, **kwargs).execute()
  File "/home/z0272571a@CAMPUS.CSIC.ES/.local/lib/python3.9/site-packages/jupyter_core/utils/__init__.py", line 165, in wrapped
    return loop.run_until_complete(inner)
  File "/home/z0272571a@CAMPUS.CSIC.ES/miniconda3/envs/centum_env/lib/python3.9/asyncio/base_events.py", line 647, in run_until_complete
    return future.result()
  File "/home/z0272571a@CAMPUS.CSIC.ES/.local/lib/python3.9/site-packages/nbclient/client.py", line 709, in async_execute
    await self.async_execute_cell(
  File "/home/z0272571a@CAMPUS.CSIC.ES/.local/lib/python3.9/site-packages/nbclient/client.py", line 1062, in async_execute_cell
    await self._check_raise_for_error(cell, cell_index, exec_reply)
  File "/home/z0272571a@CAMPUS.CSIC.ES/.local/lib/python3.9/site-packages/nbclient/client.py", line 918, in _check_raise_for_error
    raise CellExecutionError.from_cell_and_msg(cell, exec_reply_content)
nbclient.exceptions.CellExecutionError: An error occurred while executing the following cell:
------------------
ds_analysis_EO.time
------------------


[0;31m---------------------------------------------------------------------------[0m
[0;31mNameError[0m                                 Traceback (most recent call last)
Cell [0;32mIn[3], line 1[0m
[0;32m----> 1[0m [43mds_analysis_EO[49m[38;5;241m.[39mtime

[0;31mNameError[0m: name 'ds_analysis_EO' is not defined

